<robot  name="dynamixel_pro_arm" xmlns:xacro="http://www.ros.org/wiki/xacro">

  <xacro:include filename="$(find dynamixel_pro_arm_description)/urdf/joint_params.xacro" />

  <link
    name="map">
    <inertial>
      <origin
        xyz="-1.42238461288828E-17 0.048137645514438 -0.0211648338736066"
        rpy="0 0 0" />
      <mass
        value="0.322030563352372" />
      <inertia
        ixx="0.000481422612860643"
        ixy="4.66239208650874E-21"
        ixz="3.73992704955774E-20"
        iyy="0.00107338063659735"
        iyz="-3.15024410056529E-06"
        izz="0.00136401703077675" />
    </inertial>
    <visual>
      <origin
        xyz="0 0 0"
        rpy="0 0 0" />
      <geometry>
        <mesh
          filename="package://dynamixel_pro_arm_description/meshes/map.STL" />
      </geometry>
      <xacro:black/>
    </visual>
    <collision>
      <origin
        xyz="0 0 0"
        rpy="0 0 0" />
      <geometry>
        <mesh
          filename="package://dynamixel_pro_arm_description/meshes/map.STL" />
      </geometry>
    </collision>
  </link>


  <link
    name="base1">
    <inertial>
      <origin
        xyz="-0.114805862897713 0.000229931382325375 -5.78233606436738E-11"
        rpy="0 0 0" />
      <mass
        value="0.324221905796923" />
      <inertia
        ixx="0.000143673656725719"
        ixy="-4.18219329301805E-06"
        ixz="7.91596938615036E-13"
        iyy="0.000456233710044863"
        iyz="1.32176273626206E-13"
        izz="0.000455777041672725" />
    </inertial>
    <visual>
      <origin
        xyz="0 0 0"
        rpy="0 0 0" />
      <geometry>
        <mesh
          filename="package://dynamixel_pro_arm_description/meshes/base1.STL" />
      </geometry>
      <xacro:black/>
    </visual>
    <collision>
      <origin
        xyz="0 0 0"
        rpy="0 0 0" />
      <geometry>
        <mesh
          filename="package://dynamixel_pro_arm_description/meshes/base1.STL" />
      </geometry>
    </collision>
  </link>
  <joint
    name="joint0"
    type="fixed">
    <origin
      xyz="0 0.13388268590218 0.158886496469845"
      rpy="-1.5707963267949 -1.04719755119659 1.5707963267949" />
    <parent
      link="map" />
    <child
      link="base1" />
    <axis
      xyz="0 0 0" />
  </joint>
  <link
    name="base2">
    <inertial>
      <origin
        xyz="-0.0392335507073881 -7.81631318112763E-06 0.00531035516720127"
        rpy="0 0 0" />
      <mass
        value="0.0521460172856608" />
      <inertia
        ixx="0.000157538058380265"
        ixy="4.18438204231712E-09"
        ixz="5.05585752635912E-06"
        iyy="0.000153361641955115"
        iyz="-1.98448185830524E-08"
        izz="3.04077953201017E-05" />
    </inertial>
    <visual>
      <origin
        xyz="0 0 0"
        rpy="0 0 0" />
      <geometry>
        <mesh
          filename="package://dynamixel_pro_arm_description/meshes/base2.STL" />
      </geometry>
      <xacro:black/>
    </visual>
    <collision>
      <origin
        xyz="0 0 0"
        rpy="0 0 0" />
      <geometry>
        <mesh
          filename="package://dynamixel_pro_arm_description/meshes/base2.STL" />
      </geometry>
    </collision>
  </link>
  <joint
    name="joint1"
    type="revolute">
    <origin
      xyz="0 0 0"
      rpy="0.000329950722368627 -3.91151844547536E-19 1.16573417585641E-15" />
    <parent
      link="base1" />
    <child
      link="base2" />
    <axis
      xyz="1 0 0" />
      <xacro:joint1_limits/>
  </joint>
  <link
    name="base3">
    <inertial>
      <origin
        xyz="0.00111475519670734 -6.37938353531542E-09 0.00149332970653814"
        rpy="0 0 0" />
      <mass
        value="0.353415141290673" />
      <inertia
        ixx="0.000553313594150257"
        ixy="-6.59807147476319E-12"
        ixz="-4.38331554199628E-06"
        iyy="0.000556463344423009"
        iyz="1.57596600874066E-10"
        izz="0.000169663426370315" />
    </inertial>
    <visual>
      <origin
        xyz="0 0 0"
        rpy="0 0 0" />
      <geometry>
        <mesh
          filename="package://dynamixel_pro_arm_description/meshes/base3.STL" />
      </geometry>
      <xacro:black/>
    </visual>
    <collision>
      <origin
        xyz="0 0 0"
        rpy="0 0 0" />
      <geometry>
        <mesh
          filename="package://dynamixel_pro_arm_description/meshes/base3.STL" />
      </geometry>
    </collision>
  </link>
  <joint
    name="joint2"
    type="revolute">
    <origin
      xyz="0 0 0"
      rpy="1.07672117749535E-15 -3.33077071782914E-16 ${joint2_yaw_adjust -0.448514927738314}" />
    <parent
      link="base2" />
    <child
      link="base3" />
    <axis
      xyz="0 0 -1" />
      <xacro:joint2_limits/>
  </joint>
  <link
    name="base4">
    <inertial>
      <origin
        xyz="0.131279891227293 -0.0125985356508307 -2.71295075982194E-05"
        rpy="0 0 0" />
      <mass
        value="0.679540611843363" />
      <inertia
        ixx="0.000722720127994855"
        ixy="-0.00069426762871192"
        ixz="-4.11542746183462E-06"
        iyy="0.00465558408048209"
        iyz="2.74607957044618E-06"
        izz="0.00460422035673919" />
    </inertial>
    <visual>
      <origin
        xyz="0 0 0"
        rpy="0 0 0" />
      <geometry>
        <mesh
          filename="package://dynamixel_pro_arm_description/meshes/base4.STL" />
      </geometry>
      <xacro:black/>
    </visual>
    <collision>
      <origin
        xyz="0 0 0"
        rpy="0 0 0" />
      <geometry>
        <mesh
          filename="package://dynamixel_pro_arm_description/meshes/base4.STL" />
      </geometry>
    </collision>
  </link>
  <joint
    name="joint3"
    type="revolute">
    <origin
      xyz="0.034413384517151 0 0"
      rpy="3.05278468838634 -1.03419334727961E-16 -6.84174938925253E-15" />
    <parent
      link="base3" />
    <child
      link="base4" />
    <axis
      xyz="1 0 0" />
      <xacro:joint3_limits/>
  </joint>
  <link
    name="base5">
    <inertial>
      <origin
        xyz="0.11195043483619 0.0298542772733156 0.000557516625313621"
        rpy="0 0 0" />
      <mass
        value="0.233282949464609" />
      <inertia
        ixx="0.000190456810637275"
        ixy="7.84494923674009E-06"
        ixz="-1.25048796604412E-05"
        iyy="0.000740511842342998"
        iyz="-1.8210382605044E-06"
        izz="0.000658316180066946" />
    </inertial>
    <visual>
      <origin
        xyz="0 0 0"
        rpy="0 0 0" />
      <geometry>
        <mesh
          filename="package://dynamixel_pro_arm_description/meshes/base5.STL" />
      </geometry>
      <xacro:black/>
    </visual>
    <collision>
      <origin
        xyz="0 0 0"
        rpy="0 0 0" />
      <geometry>
        <mesh
          filename="package://dynamixel_pro_arm_description/meshes/base5.STL" />
      </geometry>
    </collision>
  </link>
  <joint
    name="joint4"
    type="revolute">
    <origin
      xyz="0.211586615482849 -0.0300004352331184 0"
      rpy="-1.80411241501588E-16 6.24500451351651E-17 ${joint4_yaw_adjust + -0.166489329587427}" />
    <parent
      link="base4" />
    <child
      link="base5" />
    <axis
      xyz="0 0 1" />
      <xacro:joint4_limits/>
  </joint>
  <link
    name="base6">
    <inertial>
      <origin
        xyz="0.0237751764296409 1.29683182664708E-08 -0.00139396484289391"
        rpy="0 0 0" />
      <mass
        value="0.143255965028379" />
      <inertia
        ixx="0.000101816051726741"
        ixy="1.67402255048959E-12"
        ixz="-7.17181162394316E-07"
        iyy="0.000103434698784475"
        iyz="-8.06089586271756E-11"
        izz="4.30375262150159E-05" />
    </inertial>
    <visual>
      <origin
        xyz="0 0 0"
        rpy="0 0 0" />
      <geometry>
        <mesh
          filename="package://dynamixel_pro_arm_description/meshes/base6.STL" />
      </geometry>
      <xacro:black/>
    </visual>
    <collision>
      <origin
        xyz="0 0 0"
        rpy="0 0 0" />
      <geometry>
        <mesh
          filename="package://dynamixel_pro_arm_description/meshes/base6.STL" />
      </geometry>
    </collision>
  </link>
  <joint
    name="joint5"
    type="revolute">
    <origin
      xyz="0.191364480262547 0.0300000000000002 0"
      rpy="${joint5_roll_adjust + -0.486056396438146} -2.4980018054066E-16 2.38697950294409E-15" />
    <parent
      link="base5" />
    <child
      link="base6" />
    <axis
      xyz="1 0 0" />
      <xacro:joint5_limits/>
  </joint>
  <link
    name="base7">
    <inertial>
      <origin
        xyz="0.0370221618406554 -0.000202467625949054 0.0017005635585484"
        rpy="0 0 0" />
      <mass
        value="0.0601408163501125" />
      <inertia
        ixx="5.91211534512154E-05"
        ixy="-8.77944300666587E-08"
        ixz="-1.92531044216403E-06"
        iyy="5.67480925087134E-05"
        iyz="2.07067535243446E-08"
        izz="1.77072009615194E-05" />
    </inertial>
    <visual>
      <origin
        xyz="0 0 0"
        rpy="0 0 0" />
      <geometry>
        <mesh
          filename="package://dynamixel_pro_arm_description/meshes/base7.STL" />
      </geometry>
      <xacro:black/>
    </visual>
    <collision>
      <origin
        xyz="0 0 0"
        rpy="0 0 0" />
      <geometry>
        <mesh
          filename="package://dynamixel_pro_arm_description/meshes/base7.STL" />
      </geometry>
    </collision>
  </link>
  <joint
    name="joint6"
    type="revolute">
    <origin
      xyz="0.0246355197374534 0 0"
      rpy="1.60982338570648E-15 1.16573417585641E-15 ${joint6_yaw_adjust + 0.621053840565577}" />
    <parent
      link="base6" />
    <child
      link="base7" />
    <axis
      xyz="0 0 1" />
      <xacro:joint6_limits/>
  </joint>

</robot>
